Workbook
Name CentrCostos: #REF!
Name CentrCostos: [1]Parametros!$B$3:$B$7
Name CodEgr: #REF!
Name CodEgr: [1]Parametros!$E$3:$E$22

Sheet 1ReporteImpactoYRendvs Presup
B2: I. REPORTE IMPACTO GASTO Y RENDIMIENTO VS. PRESUPUESTOS
B3: 1) RESUMEN REPORTE DE VENTAS | L3: 2) GASTO POR OP | O3: 3) PRESUPUESTO | T3: 4) DESVIACIONES REAL VS. PRESUPUESTO
L4: COSTO REAL PRODUCCION | O4: COSTO ESTIMADO DE PRODUCCION | T4: DESVIACIONES DE PRODUCCION Y GASTOS DE PRODUCCION
B5: Lote | C5: Suma de Cantidad | D5: Suma de V.Venta dol | E5: Suma de Costo dol | F5: Suma de Utilidad dol | H5: v.v. u. | I5: c.v.u. | J5: % c.v.u. | L5: Cantidad Producida según Gto. Por OP | M5: Costo Unitario de Poducc. X OP | N5: Costo de Producción Por OP | O5: hras sembradas | P5: PRODUCCION ESTIMADA POR OP | Q5: COSTO ESTIMADO POR OP | R5: COSTO X HA ESTIMADO | S5: COSTO UNITAIO POR KILO | T5: MAYOR (MENOR) VOLUMEN DE PRODUCCION | U5: MAYOR (MENOR) GASTO POR OP | V5: MAYOR (MENOR) COSTO POR RENDIMEINTO | W5: MAYOR (MENOR) COSTO TOTAL CAMPAÑO 2024 | X5: VALIDACION
B6: 01I2024 | C6: 1788121 | D6: 653759.35 | E6: 729082.48 | F6: -75323.13 | H6: =+D6/$C6 -> 0.36561248 | I6: =+E6/$C6 -> 0.40773666 | J6: =+F6/$C6 -> -0.04212418 | L6: 1788121 | M6: =N6/L6 -> 0.40773665 | N6: =+'[2]GASTO X OP'!AB54 -> 729082.46 | O6: =+[2]GastoRendPack!D6 -> 31.15 | P6: =+[2]GastoRendPack!D7 -> 1869000 | Q6: =+[2]GastoRendPack!D8 -> 439952.95 | R6: =+Q6/O6 -> 14123.69 | S6: =+Q6/P6 -> 0.23539483 | T6: =+L6-P6 -> -80879 | U6: =+N6-Q6 -> 289129.51 | V6: =(P6-L6)*S6 -> 19038.499 | W6: =(M6-S6)*L6 -> 308168.01 | X6: =+U6+V6-W6 -> 0 | Z6: =+T6/P6 -> -0.043273943
B7: 02I2024 | C7: 1820916 | D7: 637009.08 | E7: 750329.91 | F7: -113320.83 | H7: =+D7/$C7 -> 0.34982892 | I7: =+E7/$C7 -> 0.41206179 | J7: =+F7/$C7 -> -0.062232871 | L7: 1820916 | M7: =N7/L7 -> 0.4120618 | N7: =+'[2]GASTO X OP'!AB55 -> 750329.92 | O7: 37.59 | P7: =+[2]GastoRendPack!G7 -> 2255400 | Q7: =+[2]GastoRendPack!G8 -> 530909.51 | R7: =+Q7/O7 -> 14123.69 | S7: =+Q7/P7 -> 0.23539483 | T7: =+L7-P7 -> -434484 | U7: =+N7-Q7 -> 219420.41 | V7: =(P7-L7)*S7 -> 102275.29 | W7: =(M7-S7)*L7 -> 321695.7 | X7: =+U7+V7-W7 -> 0 | Z7: =+T7/P7 -> -0.19264166
B8: 03I2024 | C8: 1221003 | D8: 438831.23 | E8: 431256.93 | F8: 7574.3 | H8: =+D8/$C8 -> 0.35940225 | I8: =+E8/$C8 -> 0.35319891 | J8: =+F8/$C8 -> 0.0062033427 | L8: 1221003 | M8: =N8/L8 -> 0.3531989 | N8: =+'[2]GASTO X OP'!AB56 -> 431256.92 | O8: =+[2]GastoRendPack!J6 -> 26.81 | P8: =+[2]GastoRendPack!J7 -> 1608600 | Q8: =+[2]GastoRendPack!J8 -> 378656.13 | R8: =+Q8/O8 -> 14123.69 | S8: =+Q8/P8 -> 0.23539483 | T8: =+L8-P8 -> -387597 | U8: =+N8-Q8 -> 52600.79 | V8: =(P8-L8)*S8 -> 91238.332 | W8: =(M8-S8)*L8 -> 143839.12 | X8: =+U8+V8-W8 -> 0 | Z8: =+T8/P8 -> -0.240953
B9: 04I2024 | C9: 1055324 | D9: 359574.51 | E9: 437843.97 | F9: -78269.46 | H9: =+D9/$C9 -> 0.34072428 | I9: =+E9/$C9 -> 0.41489056 | J9: =+F9/$C9 -> -0.074166284 | L9: 1028324 | M9: =N9/L9 -> 0.42578406 | N9: =+'[2]GASTO X OP'!AB57 -> 437843.97 | O9: =+[2]GastoRendPack!M6 -> 26.58 | P9: =+[2]GastoRendPack!M7 -> 1594800 | Q9: =+[2]GastoRendPack!M8 -> 375407.68 | R9: =+Q9/O9 -> 14123.69 | S9: =+Q9/P9 -> 0.23539483 | T9: =+L9-P9 -> -566476 | U9: =+N9-Q9 -> 62436.288 | V9: =(P9-L9)*S9 -> 133345.52 | W9: =(M9-S9)*L9 -> 195781.81 | X9: =+U9+V9-W9 -> 0 | Z9: =+T9/P9 -> -0.35520191
B10: 05I2024 | C10: 852643 | D10: 306218.7 | E10: 306368.02 | F10: -149.32 | H10: =+D10/$C10 -> 0.35914058 | I10: =+E10/$C10 -> 0.3593157 | J10: =+F10/$C10 -> -0.00017512605 | L10: 852843 | M10: =N10/L10 -> 0.35923144 | N10: =+'[2]GASTO X OP'!AB58 -> 306368.02 | O10: =+[2]GastoRendPack!P6 -> 18.73 | P10: =+[2]GastoRendPack!P7 -> 1123800 | Q10: =+[2]GastoRendPack!P8 -> 264536.71 | R10: =+Q10/O10 -> 14123.69 | S10: =+Q10/P10 -> 0.23539483 | T10: =+L10-P10 -> -270957 | U10: =+N10-Q10 -> 41831.305 | V10: =(P10-L10)*S10 -> 63781.878 | W10: =(M10-S10)*L10 -> 105613.18 | X10: =+U10+V10-W10 -> 0 | Z10: =+T10/P10 -> -0.24110785
B11: 06I2024 | C11: 2375248 | D11: 837417.62 | E11: 601354.24 | F11: 236063.38 | H11: =+D11/$C11 -> 0.35256008 | I11: =+E11/$C11 -> 0.25317535 | J11: =+F11/$C11 -> 0.09938473 | L11: 2348248 | M11: =N11/L11 -> 0.25608634 | N11: =+'[2]GASTO X OP'!AB59 -> 601354.24 | O11: =+[2]GastoRendPack!S6 -> 36.43 | P11: =+[2]GastoRendPack!S7 -> 2185800 | Q11: =474957.526153846+7594 -> 482551.53 | R11: =+Q11/O11 -> 13245.993 | S11: =+Q11/P11 -> 0.22076655 | T11: =+L11-P11 -> 162448 | U11: =+N11-Q11 -> 118802.71 | V11: =(P11-L11)*S11 -> -35863.085 | W11: =(M11-S11)*L11 -> 82939.629 | X11: =+U11+V11-W11 -> 0 | Z11: =+T11/P11 -> 0.0743197
B12: 07I2024 | C12: 1889141 | D12: 668874.26 | E12: 457169.87 | F12: 211704.39 | H12: =+D12/$C12 -> 0.35406265 | I12: =+E12/$C12 -> 0.24199881 | J12: =+F12/$C12 -> 0.11206384 | L12: 1889571 | M12: =N12/L12 -> 0.24194374 | N12: =+'[2]GASTO X OP'!AB60 -> 457169.87 | O12: =+[2]GastoRendPack!V6 -> 25.7 | P12: =+[2]GastoRendPack!V7 -> 1542000 | Q12: 335064.74 | R12: =+Q12/O12 -> 13037.538 | S12: =+Q12/P12 -> 0.21729231 | T12: =+L12-P12 -> 347571 | U12: =+N12-Q12 -> 122105.13 | V12: =(P12-L12)*S12 -> -75524.505 | W12: =(M12-S12)*L12 -> 46580.627 | X12: =+U12+V12-W12 -> 0 | Z12: =+T12/P12 -> 0.22540272
B13: 08I2024 | C13: 1164201 | D13: 411418.85 | E13: 290592.79 | F13: 120826.06 | H13: =+D13/$C13 -> 0.3533916 | I13: =+E13/$C13 -> 0.24960706 | J13: =+F13/$C13 -> 0.10378454 | L13: 1165731 | M13: =N13/L13 -> 0.24927945 | N13: =+'[2]GASTO X OP'!AB61 -> 290592.78 | O13: =+[2]GastoRendPack!Y6 -> 16.89 | P13: =+[2]GastoRendPack!Y7 -> 1013400 | Q13: 220204.02 | R13: =+Q13/O13 -> 13037.538 | S13: =+Q13/P13 -> 0.21729231 | T13: =+L13-P13 -> 152331 | U13: =+N13-Q13 -> 70388.755 | V13: =(P13-L13)*S13 -> -33100.355 | W13: =(M13-S13)*L13 -> 37288.401 | X13: =+U13+V13-W13 -> 0 | Z13: =+T13/P13 -> 0.15031676
B14: 01V2024 | C14: 1025842 | D14: 373616.78 | E14: 220467.16 | F14: 153149.62 | H14: =+D14/$C14 -> 0.36420499 | I14: =+E14/$C14 -> 0.21491337 | J14: =+F14/$C14 -> 0.14929163 | L14: 1027522 | M14: =N14/L14 -> 0.21492421 | N14: =+'[2]GASTO X OP'!AB62 -> 220839.35 | O14: =+[2]GastoRendPack!BF6 -> 14.99 | P14: =+[2]GastoRendPack!BF7 -> 974350 | Q14: 211718.76 | R14: =+Q14/O14 -> 14124 | S14: =+Q14/P14 -> 0.21729231 | T14: =+L14-P14 -> 53172 | U14: =+N14-Q14 -> 9120.59 | V14: =(P14-L14)*S14 -> -11553.867 | W14: =(M14-S14)*L14 -> -2433.2766 | X14: =+U14+V14-W14 -> 9.5496944e-12 | Z14: =+T14/P14 -> 0.054571766
B15: 02V2024 | C15: 3009481.3 | D15: 791461.82 | E15: 684699.37 | F15: 106762.45 | H15: =+D15/$C15 -> 0.26298945 | I15: =+E15/$C15 -> 0.22751408 | J15: =+F15/$C15 -> 0.035475368 | L15: 3041500 | M15: =N15/L15 -> 0.22663279 | N15: =+'[2]GASTO X OP'!AB63 -> 689303.64 | O15: =+[2]GastoRendPack!BI6 -> 37.59 | P15: =+[2]GastoRendPack!BI7 -> 2443350 | Q15: =+[2]GastoRendPack!BI8 -> 530921.16 | R15: =+Q15/O15 -> 14124 | S15: =+Q15/P15 -> 0.21729231 | T15: =+L15-P15 -> 598150 | U15: =+N15-Q15 -> 158382.48 | V15: =(P15-L15)*S15 -> -129973.39 | W15: =(M15-S15)*L15 -> 28409.086 | X15: =+U15+V15-W15 -> 0 | Z15: =+T15/P15 -> 0.24480733
B16: 03V2024 | C16: 2066936.5 | D16: 349381.7 | E16: 480840.96 | F16: -131459.26 | H16: =+D16/$C16 -> 0.16903359 | I16: =+E16/$C16 -> 0.2326346 | J16: =+F16/$C16 -> -0.063601013 | L16: 2069980 | M16: =N16/L16 -> 0.23229743 | N16: =+'[2]GASTO X OP'!AB64 -> 480851.04 | O16: 26.81 | P16: =+[2]GastoRendPack!BL7 -> 1742650 | Q16: =+[2]GastoRendPack!BL8 -> 378664.44 | R16: =+Q16/O16 -> 14124 | S16: =+Q16/P16 -> 0.21729231 | T16: =+L16-P16 -> 327330 | U16: =+N16-Q16 -> 102186.6 | V16: =(P16-L16)*S16 -> -71126.291 | W16: =(M16-S16)*L16 -> 31060.309 | X16: =+U16+V16-W16 -> 0 | Z16: =+T16/P16 -> 0.18783462
B17: 04V2024 | C17: 1738635.2 | D17: 265896.53 | E17: 479355.42 | F17: -213458.89 | H17: =+D17/$C17 -> 0.15293406 | I17: =+E17/$C17 -> 0.27570788 | J17: =+F17/$C17 -> -0.12277382 | L17: 1769890 | M17: =N17/L17 -> 0.2709884 | N17: =+'[2]GASTO X OP'!AB65 -> 479619.66 | O17: 26.58 | P17: =+[2]GastoRendPack!BO7 -> 1727700 | Q17: =+[2]GastoRendPack!BO8 -> 375415.92 | R17: =+Q17/O17 -> 14124 | S17: =+Q17/P17 -> 0.21729231 | T17: =+L17-P17 -> 42190 | U17: =+N17-Q17 -> 104203.74 | V17: =(P17-L17)*S17 -> -9167.5625 | W17: =(M17-S17)*L17 -> 95036.178 | X17: =+U17+V17-W17 -> 0 | Z17: =+T17/P17 -> 0.024419749
B18: 05V2024 | C18: 575928.04 | D18: 74774.42 | E18: 182802.51 | F18: -108028.09 | H18: =+D18/$C18 -> 0.12983292 | I18: =+E18/$C18 -> 0.31740513 | J18: =+F18/$C18 -> -0.18757221 | L18: 448906 | M18: =N18/L18 -> 0.3727463 | N18: =+'[2]GASTO X OP'!AB66 -> 167328.05 | O18: 18.73 | P18: =+[2]GastoRendPack!BR7 -> 1217450 | Q18: =+[2]GastoRendPack!BR8 -> 264542.52 | R18: =+Q18/O18 -> 14124 | S18: =+Q18/P18 -> 0.21729231 | T18: =+L18-P18 -> -768544 | U18: =+N18-Q18 -> -97214.47 | V18: =(P18-L18)*S18 -> 166998.7 | W18: =(M18-S18)*L18 -> 69784.229 | X18: =+U18+V18-W18 -> 0 | Y18: =+L18/O18 -> 23967.218 | Z18: =+T18/P18 -> -0.63127356
B19: 09V2024 | C19: 2049188 | D19: 874981.49 | E19: 614287.39 | F19: 260694.1 | H19: =+D19/$C19 -> 0.42698937 | I19: =+E19/$C19 -> 0.29977112 | J19: =+F19/$C19 -> 0.12721825 | L19: 2049188 | M19: =N19/L19 -> 0.29977112 | N19: =+'[2]GASTO X OP'!AB67 -> 614287.38 | O19: 40 | P19: 2154600 | Q19: 564960 | R19: =+Q19/O19 -> 14124 | S19: =+Q19/P19 -> 0.26221108 | T19: =+L19-P19 -> -105412 | U19: =+N19-Q19 -> 49327.38 | V19: =(P19-L19)*S19 -> 27640.195 | W19: =(M19-S19)*L19 -> 76967.575 | X19: =+U19+V19-W19 -> 0 | Y19: =+L19/O19 -> 51229.7 | Z19: =+T19/P19 -> -0.048924162
B20: 07V2024 | C20: 1693057 | D20: 264091.46 | E20: 320623.45 | F20: -56531.992 | H20: =+D20/$C20 -> 0.15598498 | I20: =+E20/$C20 -> 0.18937546 | J20: =+F20/$C20 -> -0.033390483 | L20: 1668087 | M20: =N20/L20 -> 0.19221032 | N20: =+'[2]GASTO X OP'!AB68 -> 320623.54 | O20: 25.7 | P20: =+[2]GastoRendPack!BX7 -> 1670500 | Q20: =+[2]GastoRendPack!BX8 -> 362986.8 | R20: =+Q20/O20 -> 14124 | S20: =+Q20/P20 -> 0.21729231 | T20: =+L20-P20 -> -2413 | U20: =+N20-Q20 -> -42363.26 | V20: =(P20-L20)*S20 -> 524.32634 | W20: =(M20-S20)*L20 -> -41838.934 | X20: =+U20+V20-W20 -> 0 | Y20: =+L20/O20 -> 64906.109 | Z20: =+T20/P20 -> -0.0014444777
B21: 08V2024 | C21: 1083694 | D21: 166139.22 | E21: 281489.89 | F21: -115350.67 | H21: =+D21/$C21 -> 0.15330824 | I21: =+E21/$C21 -> 0.25975034 | J21: =+F21/$C21 -> -0.1064421 | L21: 1083694 | M21: =N21/L21 -> 0.25975019 | N21: =+'[2]GASTO X OP'!AB69 -> 281489.72 | O21: 23.29 | P21: =+[2]GastoRendPack!CA7 -> 1513850 | Q21: =+[2]GastoRendPack!CA8 -> 328947.96 | R21: =+Q21/O21 -> 14124 | S21: =+Q21/P21 -> 0.21729231 | T21: =+L21-P21 -> -430156 | U21: =+N21-Q21 -> -47458.24 | V21: =(P21-L21)*S21 -> 93469.59 | W21: =(M21-S21)*L21 -> 46011.35 | X21: =+U21+V21-W21 -> 0 | Y21: =+L21/O21 -> 46530.442 | Z21: =+T21/P21 -> -0.28414704
B22: 06V2024 | C22: 1433740 | D22: 228214.45 | E22: 321098.63 | F22: -92884.178 | H22: =+D22/$C22 -> 0.15917422 | I22: =+E22/$C22 -> 0.22395876 | J22: =+F22/$C22 -> -0.064784534 | L22: 1384068 | M22: =N22/L22 -> 0.22121868 | N22: =+'[2]GASTO X OP'!AB122 -> 306181.69 | O22: 36.43 | P22: =+[2]GastoRendPack!BU7 -> 2367950 | Q22: =+[2]GastoRendPack!BU8 -> 514537.32 | R22: =+Q22/O22 -> 14124 | S22: =+Q22/P22 -> 0.21729231 | T22: =+L22-P22 -> -983882 | U22: =+N22-Q22 -> -208355.63 | V22: =(P22-L22)*S22 -> 213789.99 | W22: =(M22-S22)*L22 -> 5434.3603 | X22: =+U22+V22-W22 -> 0 | Y22: =+L22/O22 -> 37992.534 | Z22: =+T22/P22 -> -0.41549948
B23: Total Genral | C23: =SUM(C6:C22) -> 26843099 | D23: =SUM(D6:D22) -> 7701661.5 | E23: =SUM(E6:E22) -> 7589663 | F23: =SUM(F6:F22) -> 111998.49 | H23: =+D23/$C23 -> 0.28691402 | I23: =+E23/$C23 -> 0.28274168 | J23: =+F23/$D23 -> 0.014542121 | L23: =SUM(L6:L22) -> 26657592 | M23: =N23/L23 -> 0.28376615 | N23: =SUM(N6:N22) -> 7564522.2 | O23: =SUM(O6:O22) -> 470 | P23: =SUM(P6:P22) -> 29005200 | Q23: =SUM(Q6:Q22) -> 6559978.2 | R23: =+Q23/O23 -> 13957.4 | S23: =Q23/P23 -> 0.22616559 | T23: =SUM(T6:T22) -> -2347608 | U23: =SUM(U6:U22) -> 1004544.1 | V23: =SUM(V6:V22) -> 545793.26 | W23: =SUM(W6:W22) -> 1550337.4 | X23: =(+M23-S23)*L23 -> 1535492.2 | Y23: =+T23/P23 -> -0.080937487 | Z23: =+T23/P23 -> -0.080937487
L24: =L23/O23 -> 56718.281 | N24: =N23/O23 -> 16094.728 | P24: =P23/O23 -> 61713.191 | Q24: =Q23/O23 -> 13957.4 | U24: =+N23-Q23 -> 1004544.1 | X24: =+X23/Q23 -> 0.23406972
J25: =+L23/27000 -> 987.31822 | L25: =+L23/O23 -> 56718.281 | P25: =+L23-P23 -> -2347608 | Q25: =+P23/27000 -> 1074.2667 | S25: =+S23*27000 -> 6106.4709 | T25: =+T23/P23 -> -0.080937487
Q28: =+Q23-Q25 -> 6558903.9 | T28: =+P24-L24 -> 4994.9106 | U28: =+T28/P24 -> 0.080937487
Q29: =+Q25*10000 -> 10742667 | R29: =+Q29/P23 -> 0.37037037
S30: =+S13*P14 -> 211718.76
S45: =807+71 -> 878

Sheet 2ResultXLote
B2: ANALISIS DEL RESULTADO POR CONTENEDOR-FACTURA DE EXPORTACION
C3: Estimado | F3: REAL | I3: Explicación Diferencia | M3: DESVIACIONES DE PRODUCCION Y GASTOS DE PRODUCCION EN PORCENTAJES
B4: Lote | C4: Valor de Venta estimado | D4: Costo de Ventas Estimado | E4: Margen Unita X Contenedor Estimado | F4: Valor de Vta Real | G4: Costo de Vtas. Real | H4: Margen Unita X Contenedor | I4: Dif. Margen Unitario | J4: Variación X Valor Vta. | K4: =-(Mayor Variación X Costo de Ventas) | M4: Mayor (Menor) Rendimiento Cantidad | N4: % Mayor (Menor) Rendimiento | O4: Mayor (Menor) costo de Producc. | P4: % Mayor (Menor) costo de Producc.
B5: 01I2024 | C5: 10000 | D5: =-'1ReporteImpactoYRendvs Presup'!S6*27000 -> -6355.6605 | E5: =+C5+D5 -> 3644.3395 | F5: =+'1ReporteImpactoYRendvs Presup'!H6*27000 -> 9871.5369 | G5: =-'1ReporteImpactoYRendvs Presup'!I6*27000 -> -11008.89 | H5: =+F5+G5 -> -1137.3528 | I5: =+H5-E5 -> -4781.6923 | J5: =+F5-C5 -> -128.46309 | K5: =+G5-D5 -> -4653.2292 | M5: =+'1ReporteImpactoYRendvs Presup'!L6-'1ReporteImpactoYRendvs Presup'!P6 -> -80879 | N5: =+M5/'1ReporteImpactoYRendvs Presup'!P6 -> -0.043273943 | O5: =+'1ReporteImpactoYRendvs Presup'!N6-'1ReporteImpactoYRendvs Presup'!Q6 -> 289129.51 | P5: =+O5/'1ReporteImpactoYRendvs Presup'!Q6 -> 0.65718281
B6: 02I2024 | C6: 10000 | D6: =-'1ReporteImpactoYRendvs Presup'!S7*27000 -> -6355.6605 | E6: =+C6+D6 -> 3644.3395 | F6: =+'1ReporteImpactoYRendvs Presup'!H7*27000 -> 9445.3809 | G6: =-'1ReporteImpactoYRendvs Presup'!I7*27000 -> -11125.668 | H6: =+F6+G6 -> -1680.2875 | I6: =+H6-E6 -> -5324.627 | J6: =+F6-C6 -> -554.61913 | K6: =+G6-D6 -> -4770.0079 | M6: =+'1ReporteImpactoYRendvs Presup'!L7-'1ReporteImpactoYRendvs Presup'!P7 -> -434484 | N6: =+M6/'1ReporteImpactoYRendvs Presup'!P7 -> -0.19264166 | O6: =+'1ReporteImpactoYRendvs Presup'!N7-'1ReporteImpactoYRendvs Presup'!Q7 -> 219420.41 | P6: =+O6/'1ReporteImpactoYRendvs Presup'!Q7 -> 0.41329154
B7: 03I2024 | C7: 10000 | D7: =-'1ReporteImpactoYRendvs Presup'!S8*27000 -> -6355.6605 | E7: =+C7+D7 -> 3644.3395 | F7: =+'1ReporteImpactoYRendvs Presup'!H8*27000 -> 9703.8609 | G7: =-'1ReporteImpactoYRendvs Presup'!I8*27000 -> -9536.3706 | H7: =+F7+G7 -> 167.49025 | I7: =+H7-E7 -> -3476.8492 | J7: =+F7-C7 -> -296.13915 | K7: =+G7-D7 -> -3180.7101 | M7: =+'1ReporteImpactoYRendvs Presup'!L8-'1ReporteImpactoYRendvs Presup'!P8 -> -387597 | N7: =+M7/'1ReporteImpactoYRendvs Presup'!P8 -> -0.240953 | O7: =+'1ReporteImpactoYRendvs Presup'!N8-'1ReporteImpactoYRendvs Presup'!Q8 -> 52600.79 | P7: =+O7/'1ReporteImpactoYRendvs Presup'!Q8 -> 0.1389144
B8: 04I2024 | C8: 10000 | D8: =-'1ReporteImpactoYRendvs Presup'!S9*27000 -> -6355.6605 | E8: =+C8+D8 -> 3644.3395 | F8: =+'1ReporteImpactoYRendvs Presup'!H9*27000 -> 9199.5556 | G8: =-'1ReporteImpactoYRendvs Presup'!I9*27000 -> -11202.045 | H8: =+F8+G8 -> -2002.4897 | I8: =+H8-E8 -> -5646.8292 | J8: =+F8-C8 -> -800.44444 | K8: =+G8-D8 -> -4846.3847 | M8: =+'1ReporteImpactoYRendvs Presup'!L9-'1ReporteImpactoYRendvs Presup'!P9 -> -566476 | N8: =+M8/'1ReporteImpactoYRendvs Presup'!P9 -> -0.35520191 | O8: =+'1ReporteImpactoYRendvs Presup'!N9-'1ReporteImpactoYRendvs Presup'!Q9 -> 62436.288 | P8: =+O8/'1ReporteImpactoYRendvs Presup'!Q9 -> 0.16631596
B9: 05I2024 | C9: 10000 | D9: =-'1ReporteImpactoYRendvs Presup'!S10*27000 -> -6355.6605 | E9: =+C9+D9 -> 3644.3395 | F9: =+'1ReporteImpactoYRendvs Presup'!H10*27000 -> 9696.7956 | G9: =-'1ReporteImpactoYRendvs Presup'!I10*27000 -> -9701.524 | H9: =+F9+G9 -> -4.7284033 | I9: =+H9-E9 -> -3649.0679 | J9: =+F9-C9 -> -303.20439 | K9: =+G9-D9 -> -3345.8635 | M9: =+'1ReporteImpactoYRendvs Presup'!L10-'1ReporteImpactoYRendvs Presup'!P10 -> -270957 | N9: =+M9/'1ReporteImpactoYRendvs Presup'!P10 -> -0.24110785 | O9: =+'1ReporteImpactoYRendvs Presup'!N10-'1ReporteImpactoYRendvs Presup'!Q10 -> 41831.305 | P9: =+O9/'1ReporteImpactoYRendvs Presup'!Q10 -> 0.15813043
B10: 06I2024 | C10: 10000 | D10: =-'1ReporteImpactoYRendvs Presup'!S11*27000 -> -5960.6969 | E10: =+C10+D10 -> 4039.3031 | F10: =+'1ReporteImpactoYRendvs Presup'!H11*27000 -> 9519.1221 | G10: =-'1ReporteImpactoYRendvs Presup'!I11*27000 -> -6835.7344 | H10: =+F10+G10 -> 2683.3877 | I10: =+H10-E10 -> -1355.9154 | J10: =+F10-C10 -> -480.8779 | K10: =+G10-D10 -> -875.03754 | M10: =+'1ReporteImpactoYRendvs Presup'!L11-'1ReporteImpactoYRendvs Presup'!P11 -> 162448 | N10: =+M10/'1ReporteImpactoYRendvs Presup'!P11 -> 0.0743197 | O10: =+'1ReporteImpactoYRendvs Presup'!N11-'1ReporteImpactoYRendvs Presup'!Q11 -> 118802.71 | P10: =+O10/'1ReporteImpactoYRendvs Presup'!Q11 -> 0.24619695
B11: 07I2024 | C11: 10000 | D11: =-'1ReporteImpactoYRendvs Presup'!S12*27000 -> -5866.8923 | E11: =+C11+D11 -> 4133.1077 | F11: =+'1ReporteImpactoYRendvs Presup'!H12*27000 -> 9559.6914 | G11: =-'1ReporteImpactoYRendvs Presup'!I12*27000 -> -6533.9678 | H11: =+F11+G11 -> 3025.7236 | I11: =+H11-E11 -> -1107.3841 | J11: =+F11-C11 -> -440.30857 | K11: =+G11-D11 -> -667.07551 | M11: =+'1ReporteImpactoYRendvs Presup'!L12-'1ReporteImpactoYRendvs Presup'!P12 -> 347571 | N11: =+M11/'1ReporteImpactoYRendvs Presup'!P12 -> 0.22540272 | O11: =+'1ReporteImpactoYRendvs Presup'!N12-'1ReporteImpactoYRendvs Presup'!Q12 -> 122105.13 | P11: =+O11/'1ReporteImpactoYRendvs Presup'!Q12 -> 0.36442251
B12: 08I2024 | C12: 10000 | D12: =-'1ReporteImpactoYRendvs Presup'!S13*27000 -> -5866.8923 | E12: =+C12+D12 -> 4133.1077 | F12: =+'1ReporteImpactoYRendvs Presup'!H13*27000 -> 9541.5731 | G12: =-'1ReporteImpactoYRendvs Presup'!I13*27000 -> -6739.3906 | H12: =+F12+G12 -> 2802.1825 | I12: =+H12-E12 -> -1330.9252 | J12: =+F12-C12 -> -458.4269 | K12: =+G12-D12 -> -872.49834 | M12: =+'1ReporteImpactoYRendvs Presup'!L13-'1ReporteImpactoYRendvs Presup'!P13 -> 152331 | N12: =+M12/'1ReporteImpactoYRendvs Presup'!P13 -> 0.15031676 | O12: =+'1ReporteImpactoYRendvs Presup'!N13-'1ReporteImpactoYRendvs Presup'!Q13 -> 70388.755 | P12: =+O12/'1ReporteImpactoYRendvs Presup'!Q13 -> 0.31965245
B13: 01V2024 | C13: 10000 | D13: =-'1ReporteImpactoYRendvs Presup'!S14*27000 -> -5866.8923 | E13: =+C13+D13 -> 4133.1077 | F13: =+'1ReporteImpactoYRendvs Presup'!H14*27000 -> 9833.5349 | G13: =-'1ReporteImpactoYRendvs Presup'!I14*27000 -> -5802.661 | H13: =+F13+G13 -> 4030.8739 | I13: =+H13-E13 -> -102.2338 | J13: =+F13-C13 -> -166.46515 | K13: =+G13-D13 -> 64.231352 | M13: =+'1ReporteImpactoYRendvs Presup'!L14-'1ReporteImpactoYRendvs Presup'!P14 -> 53172 | N13: =+M13/'1ReporteImpactoYRendvs Presup'!P14 -> 0.054571766 | O13: =+'1ReporteImpactoYRendvs Presup'!N14-'1ReporteImpactoYRendvs Presup'!Q14 -> 9120.59 | P13: =+O13/'1ReporteImpactoYRendvs Presup'!Q14 -> 0.043078799
B14: 02V2024 | C14: 10000 | D14: =-'1ReporteImpactoYRendvs Presup'!S15*27000 -> -5866.8923 | E14: =+C14+D14 -> 4133.1077 | F14: =+'1ReporteImpactoYRendvs Presup'!H15*27000 -> 7100.7151 | G14: =-'1ReporteImpactoYRendvs Presup'!I15*27000 -> -6142.8802 | H14: =+F14+G14 -> 957.83493 | I14: =+H14-E14 -> -3175.2728 | J14: =+F14-C14 -> -2899.2849 | K14: =+G14-D14 -> -275.9879 | M14: =+'1ReporteImpactoYRendvs Presup'!L15-'1ReporteImpactoYRendvs Presup'!P15 -> 598150 | N14: =+M14/'1ReporteImpactoYRendvs Presup'!P15 -> 0.24480733 | O14: =+'1ReporteImpactoYRendvs Presup'!N15-'1ReporteImpactoYRendvs Presup'!Q15 -> 158382.48 | P14: =+O14/'1ReporteImpactoYRendvs Presup'!Q15 -> 0.29831638
B15: 03V2024 | C15: 10000 | D15: =-'1ReporteImpactoYRendvs Presup'!S16*27000 -> -5866.8923 | E15: =+C15+D15 -> 4133.1077 | F15: =+'1ReporteImpactoYRendvs Presup'!H16*27000 -> 4563.9069 | G15: =-'1ReporteImpactoYRendvs Presup'!I16*27000 -> -6281.1343 | H15: =+F15+G15 -> -1717.2274 | I15: =+H15-E15 -> -5850.3351 | J15: =+F15-C15 -> -5436.0931 | K15: =+G15-D15 -> -414.24198 | M15: =+'1ReporteImpactoYRendvs Presup'!L16-'1ReporteImpactoYRendvs Presup'!P16 -> 327330 | N15: =+M15/'1ReporteImpactoYRendvs Presup'!P16 -> 0.18783462 | O15: =+'1ReporteImpactoYRendvs Presup'!N16-'1ReporteImpactoYRendvs Presup'!Q16 -> 102186.6 | P15: =+O15/'1ReporteImpactoYRendvs Presup'!Q16 -> 0.26986057
B16: 04V2024 | C16: 10000 | D16: =-'1ReporteImpactoYRendvs Presup'!S17*27000 -> -5866.8923 | E16: =+C16+D16 -> 4133.1077 | F16: =+'1ReporteImpactoYRendvs Presup'!H17*27000 -> 4129.2195 | G16: =-'1ReporteImpactoYRendvs Presup'!I17*27000 -> -7444.1127 | H16: =+F16+G16 -> -3314.8932 | I16: =+H16-E16 -> -7448.0009 | J16: =+F16-C16 -> -5870.7805 | K16: =+G16-D16 -> -1577.2204 | M16: =+'1ReporteImpactoYRendvs Presup'!L17-'1ReporteImpactoYRendvs Presup'!P17 -> 42190 | N16: =+M16/'1ReporteImpactoYRendvs Presup'!P17 -> 0.024419749 | O16: =+'1ReporteImpactoYRendvs Presup'!N17-'1ReporteImpactoYRendvs Presup'!Q17 -> 104203.74 | P16: =+O16/'1ReporteImpactoYRendvs Presup'!Q17 -> 0.27756878
... B22: Total Genral | C22: 10000 | D22: =-'1ReporteImpactoYRendvs Presup'!S23*27000 -> -6106.4709 | E22: =+C22+D22 -> 3893.5291 | F22: =+'1ReporteImpactoYRendvs Presup'!H23*27000 -> 7746.6786 | G22: =-'1ReporteImpactoYRendvs Presup'!I23*27000 -> -7634.0254 | H22: =+F22+G22 -> 112.65314 | I22: =+H22-E22 -> -3780.876 | J22: =+F22-C22 -> -2253.3214 | K22: =+G22-D22 -> -1527.5545 | M22: =+'1ReporteImpactoYRendvs Presup'!L23-'1ReporteImpactoYRendvs Presup'!P23 -> -2347608 | N22: =+M22/'1ReporteImpactoYRendvs Presup'!P23 -> -0.080937487 | O22: =+'1ReporteImpactoYRendvs Presup'!N23-'1ReporteImpactoYRendvs Presup'!Q23 -> 1004544.1 | P22: =+O22/'1ReporteImpactoYRendvs Presup'!Q23 -> 0.15313223
H23: =+H22*'1ReporteImpactoYRendvs Presup'!J25 -> 111224.49 | I23: =+I22/C22 -> -0.3780876 | J23: =+J22/C22 -> -0.22533214 | K23: =+K22/E22 -> -0.39233161

Sheet 3ComparaXRubro
B2: AGRILOR (CEBOLLA CONVENCIONAL)
B3: RESUMEN POR UNIDAD DE PRODUCCIÓN CAMPAÑA 2024-25
C4: Hetareas Sembradas | D4: Rendimeintos Kilos X Ha. | E4: Rendimeintos X Contenedor | F4: PRESUPUESTO | G4: REAL | H4: DIFERENCIAS
F5: USD | G5: USD | H5: USD
B7: ALMACIGO | F7: 782017.4 | G7: 864919.53 | H7: =+G7-F7 -> 82902.128
B8: CEBOLLA | C8: 470 | D8: =61713 -> 61713 | E8: =+D8/27000 -> 2.2856667 | F8: 5280236.7 | G8: =6040120.01-G7 -> 5175200.5 | H8: =+G8-F8 -> -105036.22
B9: PACKING | F9: 497724.23 | G9: 1524402 | H9: =+G9-F9 -> 1026677.8
B10: TOTAL | F10: =SUM(F7:F9) -> 6559978.3 | G10: =SUM(G7:G9) -> 7564522 | H10: =SUM(H7:H9) -> 1004543.7
B13: COMPARACIÓN RESUMEN POR RUBRO POR PROCESO PRODUCTIVO
B14: RESUMEN POR RUBRO | C14: PRESUPUESTO | G14: REAL | K14: DIFERENCIAS IMPORTE | O14: DIFERENCIAS PORCENTAJE
C15: ALMACIGO | D15: CAMPO DEFINITIVO | E15: PACKING | F15: TOTAL PRESUPUESTO | G15: ALMACIGO | H15: CAMPO DEFINITIVO | I15: PACKING | J15: TOTAL REAL | K15: ALMACIGO | L15: CAMPO DEFINITIVO | M15: PACKING | N15: TOTAL REAL | O15: ALMACIGO | P15: CAMPO DEFINITIVO | Q15: PACKING | R15: TOTAL REAL
B16: Semilla | C16: 546013.15 | F16: 546013.15 | G16: 502619.59 | J16: =SUM(G16:I16) -> 502619.59 | K16: =+G16-C16 -> -43393.56 | L16: =+H16-D16 -> 0 | M16: =+I16-E16 -> 0 | N16: =SUM(K16:M16) -> -43393.56 | O16: =IFERROR(+K16/C16,0) -> -0.079473471 | P16: =IFERROR(+L16/D16,0) -> 0 | Q16: =IFERROR(+M16/E16,0) -> 0 | R16: =IFERROR(+N16/F16,0) -> -0.079473471
B17: Alquiler de campo | D17: 752284 | F17: 752284 | G17: 67996.852 | H17: 611971.67 | J17: =SUM(G17:I17) -> 679968.52 | K17: =+G17-C17 -> 67996.852 | L17: =+H17-D17 -> -140312.33 | M17: =+I17-E17 -> 0 | N17: =SUM(K17:M17) -> -72315.48 | O17: =IFERROR(+K17/C17,0) -> 0 | P17: =IFERROR(+L17/D17,0) -> -0.18651511 | Q17: =IFERROR(+M17/E17,0) -> 0 | R17: =IFERROR(+N17/F17,0) -> -0.096127899
B18: Accesorios de riego | D18: 218817 | F18: 218817 | G18: 16222.068 | H18: 145998.61 | J18: =SUM(G18:I18) -> 162220.68 | K18: =+G18-C18 -> 16222.068 | L18: =+H18-D18 -> -72818.388 | M18: =+I18-E18 -> 0 | N18: =SUM(K18:M18) -> -56596.32 | O18: =IFERROR(+K18/C18,0) -> 0 | P18: =IFERROR(+L18/D18,0) -> -0.33278213 | Q18: =IFERROR(+M18/E18,0) -> 0 | R18: =IFERROR(+N18/F18,0) -> -0.25864681
B19: Materia Orgánica | C19: 42675.284 | D19: 576760.81 | F19: 619436.09 | G19: 5000 | H19: 390908.15 | J19: =SUM(G19:I19) -> 395908.15 | K19: =+G19-C19 -> -37675.284 | L19: =+H19-D19 -> -185852.66 | M19: =+I19-E19 -> 0 | N19: =SUM(K19:M19) -> -223527.94 | O19: =IFERROR(+K19/C19,0) -> -0.88283616 | P19: =IFERROR(+L19/D19,0) -> -0.32223524 | Q19: =IFERROR(+M19/E19,0) -> 0 | R19: =IFERROR(+N19/F19,0) -> -0.36085715
B20: Agua | C20: 36268.116 | D20: 455057.84 | F20: 491325.95 | G20: 20000 | H20: 353383 | J20: =SUM(G20:I20) -> 373383 | K20: =+G20-C20 -> -16268.116 | L20: =+H20-D20 -> -101674.84 | M20: =+I20-E20 -> 0 | N20: =SUM(K20:M20) -> -117942.95 | O20: =IFERROR(+K20/C20,0) -> -0.44855145 | P20: =IFERROR(+L20/D20,0) -> -0.22343278 | Q20: =IFERROR(+M20/E20,0) -> 0 | R20: =IFERROR(+N20/F20,0) -> -0.24005032
B21: Alquiler de Maquinaria | C21: 13989.355 | D21: 314257.9 | F21: 328247.26 | G21: 28716.352 | H21: 258447.17 | J21: =SUM(G21:I21) -> 287163.52 | K21: =+G21-C21 -> 14726.997 | L21: =+H21-D21 -> -55810.732 | M21: =+I21-E21 -> 0 | N21: =SUM(K21:M21) -> -41083.735 | O21: =IFERROR(+K21/C21,0) -> 1.0527288 | P21: =IFERROR(+L21/D21,0) -> -0.17759532 | Q21: =IFERROR(+M21/E21,0) -> 0 | R21: =IFERROR(+N21/F21,0) -> -0.12516094
B22: Fertilizantes / Abono Organico | C22: 51803.608 | D22: 804021 | F22: 855824.61 | G22: 71319.38 | H22: 641874.42 | J22: =SUM(G22:I22) -> 713193.8 | K22: =+G22-C22 -> 19515.772 | L22: =+H22-D22 -> -162146.58 | M22: =+I22-E22 -> 0 | N22: =SUM(K22:M22) -> -142630.81 | O22: =IFERROR(+K22/C22,0) -> 0.37672612 | P22: =IFERROR(+L22/D22,0) -> -0.20166958 | Q22: =IFERROR(+M22/E22,0) -> 0 | R22: =IFERROR(+N22/F22,0) -> -0.16665892
B23: Agroquimicos / Foliares | C23: 29437.101 | D23: 853400 | F23: 882837.1 | G23: 61576 | H23: 817333 | J23: =SUM(G23:I23) -> 878909 | K23: =+G23-C23 -> 32138.899 | L23: =+H23-D23 -> -36067 | M23: =+I23-E23 -> 0 | N23: =SUM(K23:M23) -> -3928.1014 | O23: =IFERROR(+K23/C23,0) -> 1.091782 | P23: =IFERROR(+L23/D23,0) -> -0.042262714 | Q23: =IFERROR(+M23/E23,0) -> 0 | R23: =IFERROR(+N23/F23,0) -> -0.0044494069
B24: Personal Eventual s/ contrato | C24: 61830.787 | D24: 913120 | E24: 321340.54 | F24: 1296291.3 | I24: 885359.49 | J24: =SUM(G24:I24) -> 885359.49 | K24: =+G24-C24 -> -61830.787 | L24: =+H24-D24 -> -913120 | M24: =+I24-E24 -> 564018.95 | N24: =SUM(K24:M24) -> -410931.83 | O24: =IFERROR(+K24/C24,0) -> -1 | P24: =IFERROR(+L24/D24,0) -> -1 | Q24: =IFERROR(+M24/E24,0) -> 1.7552063 | R24: =IFERROR(+N24/F24,0) -> -0.31700577
B25: Transport costs | D25: 303905.65 | E25: 11366.27 | F25: 315271.92 | G25: 27914.642 | H25: 251231.78 | J25: =SUM(G25:I25) -> 279146.42 | K25: =+G25-C25 -> 27914.642 | L25: =+H25-D25 -> -52673.871 | M25: =+I25-E25 -> -11366.27 | N25: =SUM(K25:M25) -> -36125.5 | O25: =IFERROR(+K25/C25,0) -> 0 | P25: =IFERROR(+L25/D25,0) -> -0.17332311 | Q25: =IFERROR(+M25/E25,0) -> -1 | R25: =IFERROR(+N25/F25,0) -> -0.11458521
B26: Arpillas Campo | D26: 59812.5 | E26: 107314.2 | F26: 167126.7 | G26: 14994.682 | H26: 134952.14 | J26: =SUM(G26:I26) -> 149946.82 | K26: =+G26-C26 -> 14994.682 | L26: =+H26-D26 -> 75139.638 | M26: =+I26-E26 -> -107314.2 | N26: =SUM(K26:M26) -> -17179.88 | O26: =IFERROR(+K26/C26,0) -> 0 | P26: =IFERROR(+L26/D26,0) -> 1.2562531 | Q26: =IFERROR(+M26/E26,0) -> -1 | R26: =IFERROR(+N26/F26,0) -> -0.10279554
B27: Servicio de terceros | D27: 28800 | F27: 28800 | G27: 29592 | H27: 332988.71 | J27: =SUM(G27:I27) -> 362580.71 | K27: =+G27-C27 -> 29592 | L27: =+H27-D27 -> 304188.71 | M27: =+I27-E27 -> 0 | N27: =SUM(K27:M27) -> 333780.71 | O27: =IFERROR(+K27/C27,0) -> 0 | P27: =IFERROR(+L27/D27,0) -> 10.562108 | Q27: =IFERROR(+M27/E27,0) -> 0 | R27: =IFERROR(+N27/F27,0) -> 11.589608
B28: Certificación HACCP/SENASA | E28: 7696 | F28: 7696 | G28: 0 | H28: 0 | J28: =SUM(G28:I28) -> 0 | K28: =+G28-C28 -> 0 | L28: =+H28-D28 -> 0 | M28: =+I28-E28 -> -7696 | N28: =SUM(K28:M28) -> -7696 | O28: =IFERROR(+K28/C28,0) -> 0 | P28: =IFERROR(+L28/D28,0) -> 0 | Q28: =IFERROR(+M28/E28,0) -> -1 | R28: =IFERROR(+N28/F28,0) -> -1
B29: Estiba por contenedor | E29: 31689.378 | F29: 31689.378 | G29: 0 | H29: 0 | J29: =SUM(G29:I29) -> 0 | K29: =+G29-C29 -> 0 | L29: =+H29-D29 -> 0 | M29: =+I29-E29 -> -31689.378 | N29: =SUM(K29:M29) -> -31689.378 | O29: =IFERROR(+K29/C29,0) -> 0 | P29: =IFERROR(+L29/D29,0) -> 0 | Q29: =IFERROR(+M29/E29,0) -> -1 | R29: =IFERROR(+N29/F29,0) -> -1
B30: Gas Montacargas | E30: 5837.8378 | F30: 5837.8378 | G30: 605.187 | H30: 5446.683 | J30: =SUM(G30:I30) -> 6051.87 | K30: =+G30-C30 -> 605.187 | L30: =+H30-D30 -> 5446.683 | M30: =+I30-E30 -> -5837.8378 | N30: =SUM(K30:M30) -> 214.03216 | O30: =IFERROR(+K30/C30,0) -> 0 | P30: =IFERROR(+L30/D30,0) -> 0 | Q30: =IFERROR(+M30/E30,0) -> -1 | R30: =IFERROR(+N30/F30,0) -> 0.036662917
B31: Energía Packing | E31: 12480 | F31: 12480 | G31: 363.072 | H31: 3267.648 | J31: =SUM(G31:I31) -> 3630.72 | K31: =+G31-C31 -> 363.072 | L31: =+H31-D31 -> 3267.648 | M31: =+I31-E31 -> -12480 | N31: =SUM(K31:M31) -> -8849.28 | O31: =IFERROR(+K31/C31,0) -> 0 | P31: =IFERROR(+L31/D31,0) -> 0 | Q31: =IFERROR(+M31/E31,0) -> -1 | R31: =IFERROR(+N31/F31,0) -> -0.70907692
B32: Depreciaciones | G32: 10000 | H32: 754184 | I32: 141318 | J32: =SUM(G32:I32) -> 905502 | K32: =+G32-C32 -> 10000 | L32: =+H32-D32 -> 754184 | M32: =+I32-E32 -> 141318 | N32: =SUM(K32:M32) -> 905502 | O32: =IFERROR(+K32/C32,0) -> 0 | P32: =IFERROR(+L32/D32,0) -> 0 | Q32: =IFERROR(+M32/E32,0) -> 0 | R32: =IFERROR(+N32/F32,0) -> 0
B33: MANTENIMIENTO Y REPARACION | G33: 5000 | H33: 231458.17 | J33: =SUM(G33:I33) -> 236458.17 | K33: =+G33-C33 -> 5000 | L33: =+H33-D33 -> 231458.17 | M33: =+I33-E33 -> 0 | N33: =SUM(K33:M33) -> 236458.17 | O33: =IFERROR(+K33/C33,0) -> 0 | P33: =IFERROR(+L33/D33,0) -> 0 | Q33: =IFERROR(+M33/E33,0) -> 0 | R33: =IFERROR(+N33/F33,0) -> 0
B34: SUMINISTROS | G34: 2000 | H34: 189028.38 | J34: =SUM(G34:I34) -> 191028.38 | K34: =+G34-C34 -> 2000 | L34: =+H34-D34 -> 189028.38 | M34: =+I34-E34 -> 0 | N34: =SUM(K34:M34) -> 191028.38 | O34: =IFERROR(+K34/C34,0) -> 0 | P34: =IFERROR(+L34/D34,0) -> 0 | Q34: =IFERROR(+M34/E34,0) -> 0 | R34: =IFERROR(+N34/F34,0) -> 0
B35: VARIOS | G35: 1000 | H35: 52726.851 | J35: =SUM(G35:I35) -> 53726.851 | K35: =+G35-C35 -> 1000 | L35: =+H35-D35 -> 52726.851 | M35: =+I35-E35 -> 0 | N35: =SUM(K35:M35) -> 53726.851 | O35: =IFERROR(+K35/C35,0) -> 0 | P35: =IFERROR(+L35/D35,0) -> 0 | Q35: =IFERROR(+M35/E35,0) -> 0 | R35: =IFERROR(+N35/F35,0) -> 0
B36: CAMPO DEFINITIVO | C36: =SUM(C16:C31) -> 782017.4 | D36: =SUM(D16:D31) -> 5280236.7 | E36: =SUM(E16:E31) -> 497724.23 | F36: =SUM(F16:F31) -> 6559978.3 | G36: =SUM(G16:G35) -> 864919.82 | H36: =SUM(H16:H35) -> 5175200.4 | I36: =SUM(I16:I35) -> 1026677.5 | J36: =SUM(J16:J35) -> 7066797.7 | K36: =SUM(K16:K35) -> 82902.423 | L36: =SUM(L16:L35) -> -105036.33 | M36: =SUM(M16:M35) -> 528953.27 | N36: =SUM(N16:N35) -> 506819.36 | O36: =IFERROR(+K36/C36,0) -> 0.10601097 | P36: =IFERROR(+L36/D36,0) -> -0.019892353 | Q36: =IFERROR(+M36/E36,0) -> 1.0627437 | R36: =IFERROR(+N36/F36,0) -> 0.077259304
G37: =+G36-G7 -> 0.295 | H37: =+G8 -> 5175200.5 | I37: =+H9 -> 1026677.8
H38: =+H36-H37 -> -0.113 | I38: =+I36-I37 -> -0.27797297 | P38: =+'[3]CAMP JUL 24 - JUN 25final'!BN69 -> 7595610.4
P39: =+J36-P38 -> -528812.68
B41: SHUMAN (CEBOLLA ORGANICA)
B42: RESUMEN POR UNIDAD DE PRODUCCIÓN CAMPAÑA 2024-25
C43: Hetareas Sembradas | D43: Rendimeintos Kilos X Ha. | E43: Rendimeintos X Contenedor | F43: PRESUPUESTO | G43: REAL | H43: DIFERENCIAS
F44: USD | G44: USD | H44: USD
B46: ALMACIGO | F46: 782017.4 | G46: 864919.53 | H46: =+G46-F46 -> 82902.128
...

Sheet 4GastoRealVsPresup
B1: C.Costo | D1: Cuenta | F1: Enero | I1: Febrero | L1: Marzo | O1: Abril | R1: Mayo | U1: Junio | X1: Total
A2: N° | B2: Código | C2: Descripción | D2: Código | E2: Descripción | F2: Presupuesto | G2: Ejecutado | H2: Diferencia. | I2: Presupuesto | J2: Ejecutado | K2: Diferencia. | L2: Presupuesto | M2: Ejecutado | N2: Diferencia. | O2: Presupuesto | P2: Ejecutado | Q2: Diferencia. | R2: Presupuesto | S2: Ejecutado | T2: Diferencia. | U2: Presupuesto | V2: Ejecutado | W2: Diferencia. | X2: Presupuesto | Y2: Ejecutado | Z2: Diferencia.
A3: 1 | B3: 1101 | C3: ALMACIGO CENTURY | D3: 911311 | E3: Materiales auxiliares | F3: 0 | G3: 0 | H3: 0 | I3: 0 | J3: 7.68 | K3: 7.68 | L3: 0 | M3: 0 | N3: 0 | O3: 0 | P3: 0 | Q3: 0 | R3: 0 | S3: 0 | T3: 0 | U3: 0 | V3: 0 | W3: 0 | X3: 0 | Y3: 7.68 | Z3: 0
A4: 2 | B4: 1101 | C4: ALMACIGO CENTURY | D4: 913112 | E4: Transporte de pasajeros | F4: 0 | G4: 0 | H4: 0 | I4: 0 | J4: 3300 | K4: 3300 | L4: 0 | M4: 3613.13 | N4: 3613.13 | O4: 0 | P4: 2015 | Q4: 2015 | R4: 0 | S4: 2674.09 | T4: 2674.09 | U4: 0 | V4: 0 | W4: 0 | X4: 0 | Y4: 11602.22 | Z4: 0
A5: 3 | B5: 1101 | C5: ALMACIGO CENTURY | D5: 913531 | E5: Alquiler maquinarias y equipos de explotacion | F5: 0 | G5: 0 | H5: 0 | I5: 0 | J5: 2643.5 | K5: 2643.5 | L5: 0 | M5: 1013.04 | N5: 1013.04 | O5: 0 | P5: 4682.89 | Q5: 4682.89 | R5: 0 | S5: 6216.26 | T5: 6216.26 | U5: 0 | V5: 2416.02 | W5: 2416.02 | X5: 0 | Y5: 16971.71 | Z5: 0
A6: 4 | B6: 1101 | C6: ALMACIGO CENTURY | D6: 913561 | E6: Alquiler equipos diversos | F6: 0 | G6: 0 | H6: 0 | I6: 0 | J6: 0 | K6: 0 | L6: 0 | M6: 0 | N6: 0 | O6: 0 | P6: 0 | Q6: 0 | R6: 0 | S6: 0 | T6: 0 | U6: 0 | V6: 0 | W6: 0 | X6: 0 | Y6: 0 | Z6: 0
A7: 5 | B7: 1101 | C7: ALMACIGO CENTURY | D7: 913631 | E7: Agua | F7: 0 | G7: 0 | H7: 0 | I7: 0 | J7: 1034.13 | K7: 1034.13 | L7: 0 | M7: 13319.82 | N7: 13319.82 | O7: 0 | P7: 14721.72 | Q7: 14721.72 | R7: 0 | S7: 9734.99 | T7: 9734.99 | U7: 0 | V7: 3052.62 | W7: 3052.62 | X7: 0 | Y7: 41863.28 | Z7: 0
A8: 6 | B8: 1101 | C8: ALMACIGO CENTURY | D8: 911312 | E8: SEMILLA | F8: 0 | G8: 0 | H8: 0 | I8: 0 | J8: 37599.18 | K8: 37599.18 | L8: 0 | M8: 306322.71 | N8: 306322.71 | O8: 0 | P8: 230117.94 | Q8: 230117.94 | R8: 0 | S8: 0 | T8: 0 | U8: 0 | V8: 0 | W8: 0 | X8: 0 | Y8: 574039.83 | Z8: 0
A9: 7 | B9: 1101 | C9: ALMACIGO CENTURY | D9: 911314 | E9: FERTILIZANTE | F9: 0 | G9: 0 | H9: 0 | I9: 0 | J9: 746.87 | K9: 746.87 | L9: 0 | M9: 5114.08 | N9: 5114.08 | O9: 0 | P9: 12631.7 | Q9: 12631.7 | R9: 0 | S9: 11782.63 | T9: 11782.63 | U9: 0 | V9: 7340.76 | W9: 7340.76 | X9: 0 | Y9: 37616.04 | Z9: 0
A10: 8 | B10: 1101 | C10: ALMACIGO CENTURY | D10: 911315 | E10: AGROQUIMICOS & FOLIAR | F10: 0 | G10: 0 | H10: 0 | I10: 0 | J10: 469.71 | K10: 469.71 | L10: 0 | M10: 3995.4 | N10: 3995.4 | O10: 0 | P10: 7331.66 | Q10: 7331.66 | R10: 0 | S10: 9039.31 | T10: 9039.31 | U10: 0 | V10: 6409.46 | W10: 6409.46 | X10: 0 | Y10: 27245.54 | Z10: 0
A11: 9 | B11: 1101 | C11: ALMACIGO CENTURY | D11: 911316 | E11: ACCESORIOS DE RIEGO | F11: 0 | G11: 0 | H11: 0 | I11: 0 | J11: 14932.89 | K11: 14932.89 | L11: 0 | M11: 12728.44 | N11: 12728.44 | O11: 0 | P11: 0 | Q11: 0 | R11: 0 | S11: 8530.08 | T11: 8530.08 | U11: 0 | V11: 0 | W11: 0 | X11: 0 | Y11: 36191.41 | Z11: 0
A12: 10 | B12: 1101 | C12: ALMACIGO CENTURY | D12: 911317 | E12: MATERIA ORGANICA | F12: 0 | G12: 0 | H12: 0 | I12: 0 | J12: 55048.95 | K12: 55048.95 | L12: 0 | M12: 0 | N12: 0 | O12: 0 | P12: 0 | Q12: 0 | R12: 0 | S12: 0 | T12: 0 | U12: 0 | V12: 0 | W12: 0 | X12: 0 | Y12: 55048.95 | Z12: 0
A13: 11 | B13: 1103 | C13: ALMACIGO CAMPO LINDO | D13: 913112 | E13: Transporte de pasajeros | F13: 0 | G13: 108.64 | H13: 108.64 | I13: 0 | J13: 0 | K13: 0 | L13: 0 | M13: 0 | N13: 0 | O13: 0 | P13: 0 | Q13: 0 | R13: 0 | S13: 157.3 | T13: 157.3 | U13: 0 | V13: 1940.35 | W13: 1940.35 | X13: 0 | Y13: 2206.29 | Z13: 108.64
A14: 12 | B14: 1103 | C14: ALMACIGO CAMPO LINDO | D14: 913531 | E14: Alquiler maquinarias y equipos de explotacion | F14: 0 | G14: 458.28 | H14: 458.28 | I14: 0 | J14: 0 | K14: 0 | L14: 0 | M14: 0 | N14: 0 | O14: 0 | P14: 0 | Q14: 0 | R14: 0 | S14: 0 | T14: 0 | U14: 0 | V14: 365.82 | W14: 365.82 | X14: 0 | Y14: 824.1 | Z14: 458.28
... A415: 413 | B415: 9 | C415: INGRESOS | D415: 97611 | E415: Diferencias de cambio | F415: 0 | G415: 106568.6 | H415: 106568.6 | I415: 0 | J415: 181389.72 | K415: 181389.72 | L415: 0 | M415: 83568.32 | N415: 83568.32 | O415: 0 | P415: 0.14 | Q415: 0.14 | R415: 0 | S415: 123719.45 | T415: 123719.45 | U415: 0 | V415: 1.63 | W415: 1.63 | X415: 0 | Y415: 495247.86 | Z415: 106568.6
B416: Totales | F416: 0 | G416: =SUM(G3:G415) -> 3533189.6 | H416: 7066379.2 | I416: 0 | J416: =SUM(J3:J415) -> 4198273.7 | K416: 0 | L416: 0 | M416: =SUM(M3:M415) -> 3348084 | N416: 0 | O416: 0 | P416: =SUM(P3:P415) -> 2911100 | Q416: 0 | R416: 0 | S416: =SUM(S3:S415) -> 2844456.7 | T416: 0 | U416: 0 | V416: =SUM(V3:V415) -> 2900733 | W416: 0 | X416: 0 | Y416: 19735837 | Z416: 7066379.2
Y417: =+'[4]BDC SOL'!$G$57+'[4]BDC SOL'!$G$58+'[4]BDC SOL'!$G$59+'[4]BDC SOL'!$G$60+'[4]BDC SOL'!$G$61 -> 19736212
Y418: =+Y416-Y417 -> -374.91

Sheet 5Ratios
